06/20/2023 12:10:01  [ERROR] Uncaught exception:
Traceback (most recent call last):
  File "/home/user/IDF_python/IBAStudio/NDF_gui.py", line 367, in onclick_profile
    self.new_windows.append(NDF_Fit_Figure(self, type = 'profile'))
  File "/home/user/IDF_python/IBAStudio/NDF_gui.py", line 2599, in __init__
    Window.set_profile_fit_result_plot(self, profile_params)
  File "/home/user/IDF_python/IBAStudio/NDF_gui.py", line 1655, in set_profile_fit_result_plot
    for i,name in enumerate(profile_params['names']):
TypeError: 'NoneType' object is not subscriptable

06/20/2023 01:55:00  [ERROR] Uncaught exception:
Traceback (most recent call last):
  File "/usr/lib/python3.10/runpy.py", line 196, in _run_module_as_main
    return _run_code(code, main_globals, None,
  File "/usr/lib/python3.10/runpy.py", line 86, in _run_code
    exec(code, run_globals)
  File "/home/user/.vscode/extensions/ms-python.python-2023.6.1/pythonFiles/lib/python/debugpy/adapter/../../debugpy/launcher/../../debugpy/__main__.py", line 39, in <module>
    cli.main()
  File "/home/user/.vscode/extensions/ms-python.python-2023.6.1/pythonFiles/lib/python/debugpy/adapter/../../debugpy/launcher/../../debugpy/../debugpy/server/cli.py", line 430, in main
    run()
  File "/home/user/.vscode/extensions/ms-python.python-2023.6.1/pythonFiles/lib/python/debugpy/adapter/../../debugpy/launcher/../../debugpy/../debugpy/server/cli.py", line 284, in run_file
    runpy.run_path(target, run_name="__main__")
  File "/home/user/.vscode/extensions/ms-python.python-2023.6.1/pythonFiles/lib/python/debugpy/_vendored/pydevd/_pydevd_bundle/pydevd_runpy.py", line 321, in run_path
    return _run_module_code(code, init_globals, run_name,
  File "/home/user/.vscode/extensions/ms-python.python-2023.6.1/pythonFiles/lib/python/debugpy/_vendored/pydevd/_pydevd_bundle/pydevd_runpy.py", line 135, in _run_module_code
    _run_code(code, mod_globals, init_globals,
  File "/home/user/.vscode/extensions/ms-python.python-2023.6.1/pythonFiles/lib/python/debugpy/_vendored/pydevd/_pydevd_bundle/pydevd_runpy.py", line 124, in _run_code
    exec(code, run_globals)
  File "/home/user/IDF_python/IBAStudio/NDF_gui.py", line 2791, in <module>
    if '--debug' in sys.argv:
  File "/home/user/IDF_python/IBAStudio/NDF_gui.py", line 66, in __init__
NameError: name 'os' is not defined

06/20/2023 03:23:00  [INFO] A connection to the splash screen was successfully established.
06/21/2023 05:27:10  [ERROR] Uncaught exception:
Traceback (most recent call last):
  File "/home/user/IDF_python/IBAStudio/NDF_gui.py", line 2620, in open_NDF_manual
    QDesktopServices.openUrl(path_manual)
TypeError: openUrl(QUrl): argument 1 has unexpected type 'str'

06/21/2023 05:49:54  [INFO] A connection to the splash screen was successfully established.
06/21/2023 05:51:14  [ERROR] Uncaught exception:
Traceback (most recent call last):
  File "matplotlib/backends/backend_qt.py", line 283, in enterEvent
KeyboardInterrupt

06/22/2023 02:13:00  [INFO] A connection to the splash screen was successfully established.
06/22/2023 02:22:52  [INFO] A connection to the splash screen was successfully established.
06/22/2023 02:25:29  [INFO] A connection to the splash screen was successfully established.
06/22/2023 02:30:18  [ERROR] Uncaught exception:
Traceback (most recent call last):
  File "/home/user/IDF_python/IBAStudio/NDF_gui.py", line 2624, in open_NDF_manual
    url = QUrl.fromLocalFile(path_manual)
NameError: name 'path_manual' is not defined

06/22/2023 02:30:39  [ERROR] Uncaught exception:
Traceback (most recent call last):
  File "/home/user/IDF_python/IBAStudio/NDF_gui.py", line 2624, in open_NDF_manual
    url = QUrl.fromLocalFile(self.path_manual)
AttributeError: 'bool' object has no attribute 'path_manual'

06/22/2023 02:31:03  [ERROR] Uncaught exception:
Traceback (most recent call last):
  File "/home/user/IDF_python/IBAStudio/NDF_gui.py", line 2624, in open_NDF_manual
    url = QUrl.fromLocalFile(self.manual_path)
AttributeError: 'bool' object has no attribute 'manual_path'

06/22/2023 02:31:31  [ERROR] Uncaught exception:
Traceback (most recent call last):
  File "/home/user/IDF_python/IBAStudio/NDF_gui.py", line 2624, in open_NDF_manual
    url = QUrl.fromLocalFile(self.manual_path)
AttributeError: 'bool' object has no attribute 'manual_path'

06/22/2023 02:38:21  [ERROR] Uncaught exception:
Traceback (most recent call last):
  File "/home/user/IDF_python/IBAStudio/NDF_gui.py", line 2631, in open_NDF_manual
    base_dir = os.pth.join(os.path.dirname(os.path.realpath(__file__)), 'pyIBA')
AttributeError: module 'os' has no attribute 'pth'

06/22/2023 02:38:34  [ERROR] Uncaught exception:
Traceback (most recent call last):
  File "/home/user/IDF_python/IBAStudio/NDF_gui.py", line 2633, in open_NDF_manual
    self.manual_path = os.path.join(base_dir, 'pyIBA', 'aux_files', 'MANUAL_100a.pdf')
AttributeError: 'bool' object has no attribute 'manual_path'

06/22/2023 02:42:08  [INFO] A connection to the splash screen was successfully established.
06/22/2023 03:57:04  [WARNING] run_ndf started...
06/22/2023 04:03:53  [WARNING] run_ndf started...
06/22/2023 04:05:25  [WARNING] run_ndf started...
06/22/2023 04:06:03  [WARNING] run_ndf started...
06/22/2023 04:12:39  [WARNING] run_ndf started...
06/22/2023 04:16:37  [WARNING] run_ndf started...
06/22/2023 04:16:55  [WARNING] run_ndf started...
06/22/2023 04:18:24  [WARNING] run_ndf started...
06/22/2023 04:25:19  [ERROR] Uncaught exception:
Traceback (most recent call last):
  File "/home/user/IDF_python/IBAStudio/NDF_gui.py", line 373, in onclick_profile
    self.new_windows[-1].setWindowTitle('Profile:', self.runList.currentItem().text())
TypeError: setWindowTitle(self, str): too many arguments

06/22/2023 04:25:29  [ERROR] Uncaught exception:
Traceback (most recent call last):
  File "/home/user/IDF_python/IBAStudio/NDF_gui.py", line 373, in onclick_profile
    self.new_windows[-1].setWindowTitle('Profile:', self.runList.currentItem().text())
TypeError: setWindowTitle(self, str): too many arguments

06/22/2023 04:26:08  [WARNING] run_ndf started...
06/22/2023 04:26:30  [WARNING] run_ndf started...
06/22/2023 04:26:59  [WARNING] run_ndf started...
06/22/2023 04:31:57  [WARNING] run_ndf started...
06/22/2023 04:33:20  [WARNING] run_ndf started...
06/22/2023 04:36:32  [WARNING] run_ndf started...
06/22/2023 04:38:15  [WARNING] run_ndf started...
06/22/2023 04:38:34  [WARNING] run_ndf started...
06/22/2023 04:41:19  [WARNING] run_ndf started...
06/23/2023 12:27:30  [ERROR] Uncaught exception:
Traceback (most recent call last):
  File "/usr/lib/python3.10/runpy.py", line 196, in _run_module_as_main
    return _run_code(code, main_globals, None,
  File "/usr/lib/python3.10/runpy.py", line 86, in _run_code
    exec(code, run_globals)
  File "/home/user/.vscode/extensions/ms-python.python-2023.6.1/pythonFiles/lib/python/debugpy/adapter/../../debugpy/launcher/../../debugpy/__main__.py", line 39, in <module>
    cli.main()
  File "/home/user/.vscode/extensions/ms-python.python-2023.6.1/pythonFiles/lib/python/debugpy/adapter/../../debugpy/launcher/../../debugpy/../debugpy/server/cli.py", line 430, in main
    run()
  File "/home/user/.vscode/extensions/ms-python.python-2023.6.1/pythonFiles/lib/python/debugpy/adapter/../../debugpy/launcher/../../debugpy/../debugpy/server/cli.py", line 284, in run_file
    runpy.run_path(target, run_name="__main__")
  File "/home/user/.vscode/extensions/ms-python.python-2023.6.1/pythonFiles/lib/python/debugpy/_vendored/pydevd/_pydevd_bundle/pydevd_runpy.py", line 321, in run_path
    return _run_module_code(code, init_globals, run_name,
  File "/home/user/.vscode/extensions/ms-python.python-2023.6.1/pythonFiles/lib/python/debugpy/_vendored/pydevd/_pydevd_bundle/pydevd_runpy.py", line 135, in _run_module_code
    _run_code(code, mod_globals, init_globals,
  File "/home/user/.vscode/extensions/ms-python.python-2023.6.1/pythonFiles/lib/python/debugpy/_vendored/pydevd/_pydevd_bundle/pydevd_runpy.py", line 124, in _run_code
    exec(code, run_globals)
  File "/home/user/IDF_python/IBAStudio/NDF_gui.py", line 2813, in <module>
    win = Window()
  File "/home/user/IDF_python/IBAStudio/NDF_gui.py", line 70, in __init__
    self.inicialize()
  File "/home/user/IDF_python/IBAStudio/NDF_gui.py", line 249, in inicialize
    self.ndf_more_options_window = ndf_more_options_window(self)
  File "/home/user/IDF_python/IBAStudio/ndf_more_options.py", line 38, in __init__
    print(ruthterford_file)
TypeError: setText(self, str): argument 1 has unexpected type 'SectionProxy'

06/23/2023 12:48:50  [ERROR] Uncaught exception:
Traceback (most recent call last):
  File "/usr/lib/python3.10/runpy.py", line 196, in _run_module_as_main
    return _run_code(code, main_globals, None,
  File "/usr/lib/python3.10/runpy.py", line 86, in _run_code
    exec(code, run_globals)
  File "/home/user/.vscode/extensions/ms-python.python-2023.6.1/pythonFiles/lib/python/debugpy/adapter/../../debugpy/launcher/../../debugpy/__main__.py", line 39, in <module>
    cli.main()
  File "/home/user/.vscode/extensions/ms-python.python-2023.6.1/pythonFiles/lib/python/debugpy/adapter/../../debugpy/launcher/../../debugpy/../debugpy/server/cli.py", line 430, in main
    run()
  File "/home/user/.vscode/extensions/ms-python.python-2023.6.1/pythonFiles/lib/python/debugpy/adapter/../../debugpy/launcher/../../debugpy/../debugpy/server/cli.py", line 284, in run_file
    runpy.run_path(target, run_name="__main__")
  File "/home/user/.vscode/extensions/ms-python.python-2023.6.1/pythonFiles/lib/python/debugpy/_vendored/pydevd/_pydevd_bundle/pydevd_runpy.py", line 321, in run_path
    return _run_module_code(code, init_globals, run_name,
  File "/home/user/.vscode/extensions/ms-python.python-2023.6.1/pythonFiles/lib/python/debugpy/_vendored/pydevd/_pydevd_bundle/pydevd_runpy.py", line 135, in _run_module_code
    _run_code(code, mod_globals, init_globals,
  File "/home/user/.vscode/extensions/ms-python.python-2023.6.1/pythonFiles/lib/python/debugpy/_vendored/pydevd/_pydevd_bundle/pydevd_runpy.py", line 124, in _run_code
    exec(code, run_globals)
  File "/home/user/IDF_python/IBAStudio/NDF_gui.py", line 2813, in <module>
    win = Window()
  File "/home/user/IDF_python/IBAStudio/NDF_gui.py", line 70, in __init__
    self.inicialize()
  File "/home/user/IDF_python/IBAStudio/NDF_gui.py", line 249, in inicialize
    self.ndf_more_options_window = ndf_more_options_window(self)
  File "/home/user/IDF_python/IBAStudio/ndf_more_options.py", line 39, in __init__
    text_check = 'Non-Rutherford file: ..098765432109876543210' %ruthterford_file['ebsfiles'][-28:]
TypeError: not all arguments converted during string formatting

06/23/2023 01:58:35  [ERROR] Uncaught exception:
Traceback (most recent call last):
  File "/home/user/IDF_python/IBAStudio/NDF_advanced.py", line 68, in load_advanced_inputs
    self.path_dir_tmp = self.window.path_dir + 'advanced_inputs/'
TypeError: unsupported operand type(s) for +: 'NoneType' and 'str'

06/23/2023 04:34:25  [WARNING] run_ndf started...
06/23/2023 04:34:50  [WARNING] run_ndf started...
06/23/2023 04:36:01  [WARNING] run_ndf started...
06/23/2023 04:36:16  [WARNING] run_ndf started...
06/23/2023 04:36:37  [WARNING] run_ndf started...
06/23/2023 04:37:54  [WARNING] run_ndf started...
06/23/2023 04:41:07  [WARNING] run_ndf started...
06/23/2023 04:41:38  [WARNING] run_ndf started...
06/23/2023 04:42:50  [WARNING] run_ndf started...
06/23/2023 04:43:17  [WARNING] run_ndf started...
06/23/2023 04:43:40  [WARNING] run_ndf started...
06/23/2023 04:45:11  [WARNING] run_ndf started...
06/23/2023 04:45:15  [WARNING] run_ndf started...
06/23/2023 04:46:31  [WARNING] run_ndf started...
06/23/2023 04:46:56  [WARNING] run_ndf started...
06/23/2023 04:47:20  [WARNING] run_ndf started...
06/23/2023 04:47:32  [WARNING] run_ndf started...
06/23/2023 04:48:23  [WARNING] run_ndf started...
08/04/2023 11:52:57  [INFO] A connection to the splash screen was successfully established.
08/04/2023 12:03:46  [INFO] A connection to the splash screen was successfully established.
08/04/2023 12:14:12  [ERROR] Exception occurred: 'NoneType' object is not subscriptable
08/04/2023 12:14:12  [ERROR] Uncaught exception:
Traceback (most recent call last):
  File "ndf_run_window.py", line 247, in run_ndf
    idf_file_run.export_ndf_inputs(path_dir = idf_file_run.path_dir)
  File "pyIBA/codes/NDF.py", line 1754, in export_ndf_inputs
  File "pyIBA/codes/NDF.py", line 1521, in write_geo
  File "pyIBA/codes/NDF.py", line 1054, in get_energy_calibration_fitparam
TypeError: 'NoneType' object is not subscriptable

During handling of the above exception, another exception occurred:

Traceback (most recent call last):
  File "ndf_run_window.py", line 250, in run_ndf
    tb_str = traceback.format_exception(etype=type(e), value=e, tb=e.__traceback__)
TypeError: format_exception() got an unexpected keyword argument 'etype'

08/04/2023 12:15:35  [ERROR] Exception occurred: 'NoneType' object is not subscriptable
08/04/2023 12:15:35  [ERROR] Uncaught exception:
Traceback (most recent call last):
  File "ndf_run_window.py", line 247, in run_ndf
    idf_file_run.export_ndf_inputs(path_dir = idf_file_run.path_dir)
  File "pyIBA/codes/NDF.py", line 1754, in export_ndf_inputs
  File "pyIBA/codes/NDF.py", line 1521, in write_geo
  File "pyIBA/codes/NDF.py", line 1054, in get_energy_calibration_fitparam
TypeError: 'NoneType' object is not subscriptable

During handling of the above exception, another exception occurred:

Traceback (most recent call last):
  File "ndf_run_window.py", line 250, in run_ndf
    tb_str = traceback.format_exception(etype=type(e), value=e, tb=e.__traceback__)
TypeError: format_exception() got an unexpected keyword argument 'etype'

08/04/2023 12:15:56  [ERROR] Exception occurred: 'NoneType' object is not subscriptable
08/04/2023 12:15:56  [ERROR] Uncaught exception:
Traceback (most recent call last):
  File "ndf_run_window.py", line 247, in run_ndf
    idf_file_run.export_ndf_inputs(path_dir = idf_file_run.path_dir)
  File "pyIBA/codes/NDF.py", line 1754, in export_ndf_inputs
  File "pyIBA/codes/NDF.py", line 1521, in write_geo
  File "pyIBA/codes/NDF.py", line 1054, in get_energy_calibration_fitparam
TypeError: 'NoneType' object is not subscriptable

During handling of the above exception, another exception occurred:

Traceback (most recent call last):
  File "ndf_run_window.py", line 250, in run_ndf
    tb_str = traceback.format_exception(etype=type(e), value=e, tb=e.__traceback__)
TypeError: format_exception() got an unexpected keyword argument 'etype'

08/04/2023 12:16:07  [ERROR] Exception occurred: 'NoneType' object is not subscriptable
08/04/2023 12:16:07  [ERROR] Uncaught exception:
Traceback (most recent call last):
  File "ndf_run_window.py", line 247, in run_ndf
    idf_file_run.export_ndf_inputs(path_dir = idf_file_run.path_dir)
  File "pyIBA/codes/NDF.py", line 1754, in export_ndf_inputs
  File "pyIBA/codes/NDF.py", line 1521, in write_geo
  File "pyIBA/codes/NDF.py", line 1054, in get_energy_calibration_fitparam
TypeError: 'NoneType' object is not subscriptable

During handling of the above exception, another exception occurred:

Traceback (most recent call last):
  File "ndf_run_window.py", line 250, in run_ndf
    tb_str = traceback.format_exception(etype=type(e), value=e, tb=e.__traceback__)
TypeError: format_exception() got an unexpected keyword argument 'etype'

08/04/2023 12:16:11  [ERROR] Exception occurred: 'NoneType' object is not subscriptable
08/04/2023 12:16:11  [ERROR] Uncaught exception:
Traceback (most recent call last):
  File "ndf_run_window.py", line 247, in run_ndf
    idf_file_run.export_ndf_inputs(path_dir = idf_file_run.path_dir)
  File "pyIBA/codes/NDF.py", line 1754, in export_ndf_inputs
  File "pyIBA/codes/NDF.py", line 1521, in write_geo
  File "pyIBA/codes/NDF.py", line 1054, in get_energy_calibration_fitparam
TypeError: 'NoneType' object is not subscriptable

During handling of the above exception, another exception occurred:

Traceback (most recent call last):
  File "ndf_run_window.py", line 250, in run_ndf
    tb_str = traceback.format_exception(etype=type(e), value=e, tb=e.__traceback__)
TypeError: format_exception() got an unexpected keyword argument 'etype'

08/04/2023 12:16:17  [ERROR] Exception occurred: 'NoneType' object is not subscriptable
08/04/2023 12:16:17  [ERROR] Uncaught exception:
Traceback (most recent call last):
  File "ndf_run_window.py", line 247, in run_ndf
    idf_file_run.export_ndf_inputs(path_dir = idf_file_run.path_dir)
  File "pyIBA/codes/NDF.py", line 1754, in export_ndf_inputs
  File "pyIBA/codes/NDF.py", line 1521, in write_geo
  File "pyIBA/codes/NDF.py", line 1054, in get_energy_calibration_fitparam
TypeError: 'NoneType' object is not subscriptable

During handling of the above exception, another exception occurred:

Traceback (most recent call last):
  File "ndf_run_window.py", line 250, in run_ndf
    tb_str = traceback.format_exception(etype=type(e), value=e, tb=e.__traceback__)
TypeError: format_exception() got an unexpected keyword argument 'etype'

08/04/2023 12:16:31  [ERROR] Exception occurred: 'NoneType' object is not subscriptable
08/04/2023 12:16:31  [ERROR] Uncaught exception:
Traceback (most recent call last):
  File "ndf_run_window.py", line 247, in run_ndf
    idf_file_run.export_ndf_inputs(path_dir = idf_file_run.path_dir)
  File "pyIBA/codes/NDF.py", line 1754, in export_ndf_inputs
  File "pyIBA/codes/NDF.py", line 1521, in write_geo
  File "pyIBA/codes/NDF.py", line 1054, in get_energy_calibration_fitparam
TypeError: 'NoneType' object is not subscriptable

During handling of the above exception, another exception occurred:

Traceback (most recent call last):
  File "ndf_run_window.py", line 250, in run_ndf
    tb_str = traceback.format_exception(etype=type(e), value=e, tb=e.__traceback__)
TypeError: format_exception() got an unexpected keyword argument 'etype'

08/04/2023 12:16:39  [ERROR] Exception occurred: 'NoneType' object is not subscriptable
08/04/2023 12:16:39  [ERROR] Uncaught exception:
Traceback (most recent call last):
  File "ndf_run_window.py", line 247, in run_ndf
    idf_file_run.export_ndf_inputs(path_dir = idf_file_run.path_dir)
  File "pyIBA/codes/NDF.py", line 1754, in export_ndf_inputs
  File "pyIBA/codes/NDF.py", line 1521, in write_geo
  File "pyIBA/codes/NDF.py", line 1054, in get_energy_calibration_fitparam
TypeError: 'NoneType' object is not subscriptable

During handling of the above exception, another exception occurred:

Traceback (most recent call last):
  File "ndf_run_window.py", line 250, in run_ndf
    tb_str = traceback.format_exception(etype=type(e), value=e, tb=e.__traceback__)
TypeError: format_exception() got an unexpected keyword argument 'etype'

08/04/2023 12:17:05  [INFO] A connection to the splash screen was successfully established.
08/04/2023 12:17:35  [ERROR] Exception occurred: 'NoneType' object is not subscriptable
08/04/2023 12:17:35  [ERROR] Uncaught exception:
Traceback (most recent call last):
  File "ndf_run_window.py", line 247, in run_ndf
    idf_file_run.export_ndf_inputs(path_dir = idf_file_run.path_dir)
  File "pyIBA/codes/NDF.py", line 1754, in export_ndf_inputs
  File "pyIBA/codes/NDF.py", line 1521, in write_geo
  File "pyIBA/codes/NDF.py", line 1054, in get_energy_calibration_fitparam
TypeError: 'NoneType' object is not subscriptable

During handling of the above exception, another exception occurred:

Traceback (most recent call last):
  File "ndf_run_window.py", line 250, in run_ndf
    tb_str = traceback.format_exception(etype=type(e), value=e, tb=e.__traceback__)
TypeError: format_exception() got an unexpected keyword argument 'etype'

08/04/2023 12:18:14  [ERROR] Exception occurred: 'NoneType' object is not subscriptable
08/04/2023 12:18:14  [ERROR] Uncaught exception:
Traceback (most recent call last):
  File "ndf_run_window.py", line 247, in run_ndf
    idf_file_run.export_ndf_inputs(path_dir = idf_file_run.path_dir)
  File "pyIBA/codes/NDF.py", line 1754, in export_ndf_inputs
  File "pyIBA/codes/NDF.py", line 1521, in write_geo
  File "pyIBA/codes/NDF.py", line 1054, in get_energy_calibration_fitparam
TypeError: 'NoneType' object is not subscriptable

During handling of the above exception, another exception occurred:

Traceback (most recent call last):
  File "ndf_run_window.py", line 250, in run_ndf
    tb_str = traceback.format_exception(etype=type(e), value=e, tb=e.__traceback__)
TypeError: format_exception() got an unexpected keyword argument 'etype'

08/04/2023 12:18:39  [INFO] A connection to the splash screen was successfully established.
08/04/2023 12:19:45  [INFO] A connection to the splash screen was successfully established.
08/04/2023 12:20:12  [ERROR] Exception occurred: 'NoneType' object is not subscriptable
08/04/2023 12:20:12  [ERROR] Uncaught exception:
Traceback (most recent call last):
  File "ndf_run_window.py", line 247, in run_ndf
    idf_file_run.export_ndf_inputs(path_dir = idf_file_run.path_dir)
  File "pyIBA/codes/NDF.py", line 1754, in export_ndf_inputs
  File "pyIBA/codes/NDF.py", line 1521, in write_geo
  File "pyIBA/codes/NDF.py", line 1054, in get_energy_calibration_fitparam
TypeError: 'NoneType' object is not subscriptable

During handling of the above exception, another exception occurred:

Traceback (most recent call last):
  File "ndf_run_window.py", line 250, in run_ndf
    tb_str = traceback.format_exception(etype=type(e), value=e, tb=e.__traceback__)
TypeError: format_exception() got an unexpected keyword argument 'etype'

08/04/2023 12:21:12  [ERROR] Exception occurred: 'NoneType' object is not subscriptable
08/04/2023 12:21:12  [ERROR] Uncaught exception:
Traceback (most recent call last):
  File "ndf_run_window.py", line 247, in run_ndf
    idf_file_run.export_ndf_inputs(path_dir = idf_file_run.path_dir)
  File "pyIBA/codes/NDF.py", line 1754, in export_ndf_inputs
  File "pyIBA/codes/NDF.py", line 1521, in write_geo
  File "pyIBA/codes/NDF.py", line 1054, in get_energy_calibration_fitparam
TypeError: 'NoneType' object is not subscriptable

During handling of the above exception, another exception occurred:

Traceback (most recent call last):
  File "ndf_run_window.py", line 250, in run_ndf
    tb_str = traceback.format_exception(etype=type(e), value=e, tb=e.__traceback__)
TypeError: format_exception() got an unexpected keyword argument 'etype'

08/04/2023 12:21:56  [ERROR] Exception occurred: 'NoneType' object is not subscriptable
08/04/2023 12:21:56  [ERROR] Uncaught exception:
Traceback (most recent call last):
  File "ndf_run_window.py", line 247, in run_ndf
    idf_file_run.export_ndf_inputs(path_dir = idf_file_run.path_dir)
  File "pyIBA/codes/NDF.py", line 1754, in export_ndf_inputs
  File "pyIBA/codes/NDF.py", line 1521, in write_geo
  File "pyIBA/codes/NDF.py", line 1054, in get_energy_calibration_fitparam
TypeError: 'NoneType' object is not subscriptable

During handling of the above exception, another exception occurred:

Traceback (most recent call last):
  File "ndf_run_window.py", line 250, in run_ndf
    tb_str = traceback.format_exception(etype=type(e), value=e, tb=e.__traceback__)
TypeError: format_exception() got an unexpected keyword argument 'etype'

08/04/2023 12:22:08  [ERROR] Uncaught exception:
Traceback (most recent call last):
  File "NDF_gui.py", line 455, in onchange_comboSimulation
    self.simulation_id = self.comboSimulation.currentIndex()
  File "NDF_gui.py", line 533, in simulation_id
    self.set_geometry_fit_box()
  File "NDF_gui.py", line 1195, in set_geometry_fit_box
    value = p['method'](spectra_id = self.spectra_id, simulation_id=self.simulation_id)
  File "pyIBA/codes/NDF.py", line 1054, in get_energy_calibration_fitparam
TypeError: 'NoneType' object is not subscriptable

08/04/2023 12:22:19  [ERROR] Uncaught exception:
Traceback (most recent call last):
  File "NDF_gui.py", line 455, in onchange_comboSimulation
    self.simulation_id = self.comboSimulation.currentIndex()
  File "NDF_gui.py", line 533, in simulation_id
    self.set_geometry_fit_box()
  File "NDF_gui.py", line 1195, in set_geometry_fit_box
    value = p['method'](spectra_id = self.spectra_id, simulation_id=self.simulation_id)
  File "pyIBA/codes/NDF.py", line 1054, in get_energy_calibration_fitparam
TypeError: 'NoneType' object is not subscriptable

08/04/2023 12:22:21  [ERROR] Uncaught exception:
Traceback (most recent call last):
  File "NDF_gui.py", line 455, in onchange_comboSimulation
    self.simulation_id = self.comboSimulation.currentIndex()
  File "NDF_gui.py", line 533, in simulation_id
    self.set_geometry_fit_box()
  File "NDF_gui.py", line 1195, in set_geometry_fit_box
    value = p['method'](spectra_id = self.spectra_id, simulation_id=self.simulation_id)
  File "pyIBA/codes/NDF.py", line 1054, in get_energy_calibration_fitparam
TypeError: 'NoneType' object is not subscriptable

08/04/2023 12:22:22  [ERROR] Uncaught exception:
Traceback (most recent call last):
  File "NDF_gui.py", line 455, in onchange_comboSimulation
    self.simulation_id = self.comboSimulation.currentIndex()
  File "NDF_gui.py", line 533, in simulation_id
    self.set_geometry_fit_box()
  File "NDF_gui.py", line 1195, in set_geometry_fit_box
    value = p['method'](spectra_id = self.spectra_id, simulation_id=self.simulation_id)
  File "pyIBA/codes/NDF.py", line 1054, in get_energy_calibration_fitparam
TypeError: 'NoneType' object is not subscriptable

08/04/2023 12:22:24  [ERROR] Uncaught exception:
Traceback (most recent call last):
  File "NDF_gui.py", line 455, in onchange_comboSimulation
    self.simulation_id = self.comboSimulation.currentIndex()
  File "NDF_gui.py", line 533, in simulation_id
    self.set_geometry_fit_box()
  File "NDF_gui.py", line 1195, in set_geometry_fit_box
    value = p['method'](spectra_id = self.spectra_id, simulation_id=self.simulation_id)
  File "pyIBA/codes/NDF.py", line 1054, in get_energy_calibration_fitparam
TypeError: 'NoneType' object is not subscriptable

08/04/2023 12:22:34  [ERROR] Uncaught exception:
Traceback (most recent call last):
  File "NDF_gui.py", line 455, in onchange_comboSimulation
    self.simulation_id = self.comboSimulation.currentIndex()
  File "NDF_gui.py", line 533, in simulation_id
    self.set_geometry_fit_box()
  File "NDF_gui.py", line 1195, in set_geometry_fit_box
    value = p['method'](spectra_id = self.spectra_id, simulation_id=self.simulation_id)
  File "pyIBA/codes/NDF.py", line 1054, in get_energy_calibration_fitparam
TypeError: 'NoneType' object is not subscriptable

08/04/2023 12:22:43  [ERROR] Uncaught exception:
Traceback (most recent call last):
  File "NDF_gui.py", line 455, in onchange_comboSimulation
    self.simulation_id = self.comboSimulation.currentIndex()
  File "NDF_gui.py", line 533, in simulation_id
    self.set_geometry_fit_box()
  File "NDF_gui.py", line 1195, in set_geometry_fit_box
    value = p['method'](spectra_id = self.spectra_id, simulation_id=self.simulation_id)
  File "pyIBA/codes/NDF.py", line 1054, in get_energy_calibration_fitparam
TypeError: 'NoneType' object is not subscriptable

08/04/2023 02:05:34  [WARNING] run_ndf started...
08/04/2023 02:05:34  [ERROR] Exception occurred: 'NoneType' object is not subscriptable
08/04/2023 02:05:34  [ERROR] Uncaught exception:
Traceback (most recent call last):
  File "/home/user/IDF_python/IBAStudio/ndf_run_window.py", line 247, in run_ndf
    idf_file_run.export_ndf_inputs(path_dir = idf_file_run.path_dir)
  File "/home/user/IDF_python/IBAStudio/pyIBA/pyIBA/codes/NDF.py", line 1754, in export_ndf_inputs
    self.write_geo(path_dir = path_dir, spectra_id = i)
  File "/home/user/IDF_python/IBAStudio/pyIBA/pyIBA/codes/NDF.py", line 1521, in write_geo
    calibration = self.get_energy_calibration_fitparam(spectra_id = spectra_id, simulation_id = i)
  File "/home/user/IDF_python/IBAStudio/pyIBA/pyIBA/codes/NDF.py", line 1054, in get_energy_calibration_fitparam
    fit_param = get_xml_section(ndf_entry, 'ndf:fitparameters')[0]
TypeError: 'NoneType' object is not subscriptable

During handling of the above exception, another exception occurred:

Traceback (most recent call last):
  File "/home/user/IDF_python/IBAStudio/ndf_run_window.py", line 250, in run_ndf
    tb_str = traceback.format_exception(etype=type(e), value=e, tb=e.__traceback__)
TypeError: format_exception() got an unexpected keyword argument 'etype'

08/04/2023 02:08:03  [WARNING] run_ndf started...
08/04/2023 02:08:03  [ERROR] Exception occurred: 'NoneType' object is not subscriptable
08/04/2023 02:08:03  [ERROR] Uncaught exception:
Traceback (most recent call last):
  File "/home/user/IDF_python/IBAStudio/ndf_run_window.py", line 247, in run_ndf
    idf_file_run.export_ndf_inputs(path_dir = idf_file_run.path_dir)
  File "/home/user/IDF_python/IBAStudio/pyIBA/pyIBA/codes/NDF.py", line 1754, in export_ndf_inputs
    self.write_geo(path_dir = path_dir, spectra_id = i)
  File "/home/user/IDF_python/IBAStudio/pyIBA/pyIBA/codes/NDF.py", line 1521, in write_geo
    calibration = self.get_energy_calibration_fitparam(spectra_id = spectra_id, simulation_id = i)
  File "/home/user/IDF_python/IBAStudio/pyIBA/pyIBA/codes/NDF.py", line 1054, in get_energy_calibration_fitparam
    fit_param = get_xml_section(ndf_entry, 'ndf:fitparameters')[0]
TypeError: 'NoneType' object is not subscriptable

During handling of the above exception, another exception occurred:

Traceback (most recent call last):
  File "/home/user/IDF_python/IBAStudio/ndf_run_window.py", line 250, in run_ndf
    tb_str = traceback.format_exception(etype=type(e), value=e, tb=e.__traceback__)
TypeError: format_exception() got an unexpected keyword argument 'etype'

08/04/2023 02:11:22  [ERROR] Uncaught exception:
Traceback (most recent call last):
  File "/home/user/IDF_python/IBAStudio/NDF_gui.py", line 693, in open
    self.reload_window()
  File "/home/user/IDF_python/IBAStudio/NDF_gui.py", line 931, in reload_window
    self.set_geometry_fit_box()
  File "/home/user/IDF_python/IBAStudio/NDF_gui.py", line 1195, in set_geometry_fit_box
    value = p['method'](spectra_id = self.spectra_id, simulation_id=self.simulation_id)
  File "/home/user/IDF_python/IBAStudio/pyIBA/pyIBA/codes/NDF.py", line 1055, in get_energy_calibration_fitparam
    if fit_param_section is None or len(fit_param) == 0:
NameError: name 'fit_param_section' is not defined

During handling of the above exception, another exception occurred:

Traceback (most recent call last):
  File "/home/user/IDF_python/IBAStudio/NDF_gui.py", line 719, in open
    if self.debug: raise e
  File "/home/user/IDF_python/IBAStudio/NDF_gui.py", line 705, in open
    self.reload_window()
  File "/home/user/IDF_python/IBAStudio/NDF_gui.py", line 931, in reload_window
    self.set_geometry_fit_box()
  File "/home/user/IDF_python/IBAStudio/NDF_gui.py", line 1195, in set_geometry_fit_box
    value = p['method'](spectra_id = self.spectra_id, simulation_id=self.simulation_id)
  File "/home/user/IDF_python/IBAStudio/pyIBA/pyIBA/codes/NDF.py", line 1055, in get_energy_calibration_fitparam
    if fit_param_section is None or len(fit_param) == 0:
NameError: name 'fit_param_section' is not defined

08/04/2023 02:12:00  [ERROR] Uncaught exception:
Traceback (most recent call last):
  File "/home/user/IDF_python/IBAStudio/NDF_gui.py", line 693, in open
    self.reload_window()
  File "/home/user/IDF_python/IBAStudio/NDF_gui.py", line 931, in reload_window
    self.set_geometry_fit_box()
  File "/home/user/IDF_python/IBAStudio/NDF_gui.py", line 1195, in set_geometry_fit_box
    value = p['method'](spectra_id = self.spectra_id, simulation_id=self.simulation_id)
  File "/home/user/IDF_python/IBAStudio/pyIBA/pyIBA/codes/NDF.py", line 1055, in get_energy_calibration_fitparam
    if fit_param is None or len(fit_param) == 0:
TypeError: object of type 'Element' has no len()

During handling of the above exception, another exception occurred:

Traceback (most recent call last):
  File "/home/user/IDF_python/IBAStudio/NDF_gui.py", line 719, in open
    if self.debug: raise e
  File "/home/user/IDF_python/IBAStudio/NDF_gui.py", line 705, in open
    self.reload_window()
  File "/home/user/IDF_python/IBAStudio/NDF_gui.py", line 931, in reload_window
    self.set_geometry_fit_box()
  File "/home/user/IDF_python/IBAStudio/NDF_gui.py", line 1195, in set_geometry_fit_box
    value = p['method'](spectra_id = self.spectra_id, simulation_id=self.simulation_id)
  File "/home/user/IDF_python/IBAStudio/pyIBA/pyIBA/codes/NDF.py", line 1055, in get_energy_calibration_fitparam
    if fit_param is None or len(fit_param) == 0:
TypeError: object of type 'Element' has no len()

08/04/2023 02:13:15  [WARNING] run_ndf started...
08/04/2023 02:13:16  [ERROR] Exception occurred: 'NoneType' object is not subscriptable
08/04/2023 02:13:16  [ERROR] Uncaught exception:
Traceback (most recent call last):
  File "/home/user/IDF_python/IBAStudio/ndf_run_window.py", line 247, in run_ndf
    idf_file_run.export_ndf_inputs(path_dir = idf_file_run.path_dir)
  File "/home/user/IDF_python/IBAStudio/pyIBA/pyIBA/codes/NDF.py", line 1757, in export_ndf_inputs
    self.write_geo(path_dir = path_dir, spectra_id = i)
  File "/home/user/IDF_python/IBAStudio/pyIBA/pyIBA/codes/NDF.py", line 1524, in write_geo
    calibration = self.get_energy_calibration_fitparam(spectra_id = spectra_id, simulation_id = i)
  File "/home/user/IDF_python/IBAStudio/pyIBA/pyIBA/codes/NDF.py", line 1054, in get_energy_calibration_fitparam
    fit_param = get_xml_section(ndf_entry, 'ndf:fitparameters')[0]
TypeError: 'NoneType' object is not subscriptable

During handling of the above exception, another exception occurred:

Traceback (most recent call last):
  File "/home/user/IDF_python/IBAStudio/ndf_run_window.py", line 250, in run_ndf
    tb_str = traceback.format_exception(etype=type(e), value=e, tb=e.__traceback__)
TypeError: format_exception() got an unexpected keyword argument 'etype'

08/04/2023 02:14:29  [WARNING] run_ndf started...
08/04/2023 02:16:03  [WARNING] run_ndf started...
08/04/2023 02:17:42  [WARNING] run_ndf started...
08/04/2023 02:18:14  [WARNING] run_ndf started...
08/04/2023 02:19:36  [WARNING] run_ndf started...
08/04/2023 02:20:07  [WARNING] run_ndf started...
08/04/2023 02:20:46  [WARNING] run_ndf started...
08/04/2023 02:21:22  [WARNING] run_ndf started...
08/04/2023 02:21:49  [WARNING] run_ndf started...
08/04/2023 02:22:34  [WARNING] run_ndf started...
08/04/2023 02:28:19  [WARNING] run_ndf started...
08/04/2023 02:28:40  [WARNING] run_ndf started...
08/04/2023 04:40:36  [WARNING] run_ndf started...
08/04/2023 04:42:55  [WARNING] run_ndf started...
08/04/2023 05:38:34  [ERROR] Uncaught exception:
Traceback (most recent call last):
  File "/home/user/IDF_python/IBAStudio/NDF_gui.py", line 373, in onclick_profile
    self.new_windows[-1].setWindowTitle('Profile:', self.runList.currentItem().text())
TypeError: setWindowTitle(self, str): too many arguments

08/04/2023 05:38:42  [ERROR] Uncaught exception:
Traceback (most recent call last):
  File "/home/user/IDF_python/IBAStudio/NDF_gui.py", line 373, in onclick_profile
    self.new_windows[-1].setWindowTitle('Profile:', self.runList.currentItem().text())
TypeError: setWindowTitle(self, str): too many arguments

